Workbook

Sheet Read me
B2: Database design decision matrix
B3: Identity, privilege ladder, organisation model, governance and audit
B5: What this is | C5: The auditable companion to the interactive questionnaire. The questionnaire produces a recommendation; this workbook shows the working, so a reviewer can see exactly which answer produced which recommendation and on what authority.
B7: How to use it | C7: 1. Fill the yellow column on the Answers sheet. Codes come from the Question bank sheet; separate multiple codes with a semicolon (for example: pw;pksync;totp).
C8: 2. Open Conflict checks. Any row reading FIRES is a combination of your answers that cannot hold, or that you should decide about deliberately. Contradictions come first.
C9: 3. Read Decision rules top to bottom for your case. Each row gives one primary choice, one alternative, and the condition that should make you switch.
C10: 4. Use Role matrix, Regime clocks and Authenticators as reference tables while you draft the schema.
B12: Legend | C12: Yellow cells are yours to edit. Everything else is reference data or a formula. The Answers column arrives pre-filled with one worked example (a mid-size B2B SaaS) so the conflict formulas have something to evaluate - overwrite it.
B14: What it does not do | C14: It does not replace the questionnaire, which branches: it hides questions that do not apply to you and asks domain-specific ones that do. This workbook lists every question in the bank, including ones your case will never need. The Shown when column on the Answers sheet tells you which.
C15: It is not legal advice. The Regime clocks sheet summarises published obligations to help you shape a schema; confirm each against the current instrument for your jurisdictions.
B17: Contents
B18: Sheet | C18: What is on it | D18: Rows
B19: Answers | C19: Every question in the bank, with the yellow column for your answers. | D19: =COUNTA(Answers!A:A)-1 -> 113
B20: Conflict checks | C20: Live formulas over your answers. FIRES means the combination is a problem. | D20: =COUNTA('Conflict checks'!A:A)-1 -> 31
B21: Decision rules | C21: Condition, primary, alternative, switch-when, evidence. The matrix proper. | D21: =COUNTA('Decision rules'!A:A)-1 -> 74
B22: Question bank | C22: Every answer code and what it means. Use this to fill the Answers sheet. | D22: =COUNTA('Question bank'!A:A)-1 -> 669
B23: Role matrix | C23: A worked starter permission set, and the separations that matter. | D23: =COUNTA('Role matrix'!B:B)-1 -> 18
B24: Regime clocks | C24: Breach, erasure, residency and retention obligations side by side. | D24: =COUNTA('Regime clocks'!B:B)-1 -> 7
B25: Authenticators | C25: Assurance ceiling, phishing resistance and the schema fields each type needs. | D25: =COUNTA(Authenticators!B:B)-1 -> 10
B26: Evidence | C26: The source behind every citation key used in this workbook. | D26: =COUNTA(Evidence!A:A)-1 -> 56
B28: Status of your answers
B29: Questions in the bank | C29: =COUNTA(Answers!A:A)-1 -> 113
B30: Answered | C30: =COUNTIF(Answers!$J$2:$J$200,"yes") -> 91
B31: Still blank | C31: =(COUNTA(Answers!A:A)-1)-COUNTIF(Answers!$J$2:$J$200,"yes") -> 22
B32: Contradictions firing | C32: =COUNTIFS('Conflict checks'!$B$2:$B$200,"Contradiction",'Conflict checks'!$C$2:$C$200,"FIRES") -> 0
B33: Risks firing | C33: =COUNTIFS('Conflict checks'!$B$2:$B$200,"Risk",'Conflict checks'!$C$2:$C$200,"FIRES") -> 0
B34: Items to consider | C34: =COUNTIFS('Conflict checks'!$B$2:$B$200,"Consider",'Conflict checks'!$C$2:$C$200,"FIRES") -> 0
B36: Assumptions in this workbook
C37: - Every recommendation is conditional on an answer. Nothing here is a default derived from popularity; where a rule fires on "otherwise", the row says so explicitly.
C38: - Version and date claims (PostgreSQL 18 current with 19 expected September 2026; NIST SP 800-63-4 final 31 July 2025; WebAuthn L3 still a Candidate Recommendation Snapshot dated 26 May 2026; CTAP 2.3 Proposed Standard February 2026; OAuth 2.1 still an Internet-Draft, so RFC 9700 is cited instead) were accurate when compiled. Re-check before quoting them.
C39: - Vendor pricing is deliberately absent. It changes faster than any document can track, and the tier boundaries are where the surprises live.
C40: - Benchmark figures quoted in the Decision rules sheet come from the published sources named in the Evidence sheet. They are indicative of shape, not guarantees for your hardware.

Sheet Answers
A1: ID | B1: Section | C1: Question | D1: Type | E1: Required | F1: Shown when | G1: Your answer (codes) | H1: Custom / "other" text | I1: Note | J1: Answered?
A2: A1 | B2: Domain & risk | C2: Which best describes what the system is for? | D2: single | E2: yes | F2: always | G2: b2bsaas | J2: =IF(LEN(TRIM(G2))>0,"yes","-") -> yes
A3: A2 | B3: Domain & risk | C3: Who will hold accounts in the system? | D3: multi | E3: yes | F3: always | G3: custstaff;ownstaff | J3: =IF(LEN(TRIM(G3))>0,"yes","-") -> yes
A4: A3 | B4: Domain & risk | C4: Is the system multi-tenant? | D4: single | E4: yes | F4: always | G4: shared | J4: =IF(LEN(TRIM(G4))>0,"yes","-") -> yes
A5: A4 | B5: Domain & risk | C5: What is the worst realistic consequence of a wrong, lost or leaked record? | D5: single | E5: yes | F5: always | G5: reput | J5: =IF(LEN(TRIM(G5))>0,"yes","-") -> yes
A6: A5 | B6: Domain & risk | C6: Does the system do any of these regulated things? | D6: multi | E6: yes | F6: always | G6: none | J6: =IF(LEN(TRIM(G6))>0,"yes","-") -> yes
A7: B1 | B7: Scale & data shape | C7: How many rows will your largest single table hold 24 months after launch? | D7: single | E7: yes | F7: always | G7: small | J7: =IF(LEN(TRIM(G7))>0,"yes","-") -> yes
A8: B2 | B8: Scale & data shape | C8: What is the read-to-write ratio on the busiest path? | D8: single | E8: yes | F8: always | G8: balanced | J8: =IF(LEN(TRIM(G8))>0,"yes","-") -> yes
A9: B3 | B9: Scale & data shape | C9: Peak concurrent active users or connections at the busiest minute? | D9: single | E9: yes | F9: always | G9: p2 | J9: =IF(LEN(TRIM(G9))>0,"yes","-") -> yes
A10: B4 | B10: Scale & data shape | C10: Does the dominant data have a time axis — is it a stream of dated events? | D10: single | E10: yes | F10: always | G10: secondary | J10: =IF(LEN(TRIM(G10))>0,"yes","-") -> yes
A11: B5 | B11: Scale & data shape | C11: How variable is the shape of your records? | D11: single | E11: yes | F11: always | G11: mostly | J11: =IF(LEN(TRIM(G11))>0,"yes","-") -> yes
A12: B6 | B12: Scale & data shape | C12: Where are your users, physically? | D12: single | E12: yes | F12: always | G12: region | J12: =IF(LEN(TRIM(G12))>0,"yes","-") -> yes
A13: B7 | B13: Scale & data shape | C13: What kind of search do users need? | D13: single | E13: yes | F13: always | G13: fts | J13: =IF(LEN(TRIM(G13))>0,"yes","-") -> yes
... A52: G5 | B52: Staff & roles | C52: Which duties must never be held by the same person at the same time? | D52: multi | E52: yes | F52: always | G52: none | J52: =IF(LEN(TRIM(G52))>0,"yes","-") -> yes
A53: G6 | B53: Staff & roles | C53: Is access tied to a shift, roster or opening hours? | D53: single | E53: yes | F53: one of A2,ownstaff,contract OR one of F1,branch,ward | J53: =IF(LEN(TRIM(G53))>0,"yes","-") -> -
A54: G7 | B54: Staff & roles | C54: Do staff share a physical terminal, till or workstation? | D54: single | E54: yes | F54: one of F1,branch,ward OR one of A1,commerce,health,logistics | J54: =IF(LEN(TRIM(G54))>0,"yes","-") -> -
A55: G8 | B55: Staff & roles | C55: Do you have field or mobile staff with unreliable connectivity? | D55: single | E55: yes | F55: one of A1,logistics,health,commerce,gov OR B10,full | J55: =IF(LEN(TRIM(G55))>0,"yes","-") -> -
A56: G9 | B56: Staff & roles | C56: Do contractor or partner accounts need a hard expiry? | D56: single | E56: yes | F56: one of A2,contract,partner | G56: date | J56: =IF(LEN(TRIM(G56))>0,"yes","-") -> yes
A57: H1 | B57: Admin & super-admin | C57: Can an administrator create new roles, or only use the ones you ship? | D57: single | E57: yes | F57: always | G57: delta | J57: =IF(LEN(TRIM(G57))>0,"yes","-") -> yes
A58: H2 | B58: Admin & super-admin | C58: Who is allowed to grant what? | D58: single | E58: yes | F58: always | G58: subset | J58: =IF(LEN(TRIM(G58))>0,"yes","-") -> yes
A59: H3 | B59: Admin & super-admin | C59: How should the highest level of access work? | D59: single | E59: yes | F59: always | G59: break | J59: =IF(LEN(TRIM(G59))>0,"yes","-") -> yes
A60: H4 | B60: Admin & super-admin | C60: Does support staff need to see or use the product as a specific user? | D60: single | E60: yes | F60: always | G60: readonly | J60: =IF(LEN(TRIM(G60))>0,"yes","-") -> yes
A61: H5 | B61: Admin & super-admin | C61: Which administrative actions need a second person to approve them? | D61: multi | E61: yes | F61: always | G61: grant | J61: =IF(LEN(TRIM(G61))>0,"yes","-") -> yes
A62: H6 | B62: Admin & super-admin | C62: Do you need periodic access reviews? | D62: single | E62: yes | F62: always | G62: periodic | J62: =IF(LEN(TRIM(G62))>0,"yes","-") -> yes
A63: H7 | B63: Admin & super-admin | C63: What must administrators be able to see? | D63: multi | E63: yes | F63: always | G63: users;access;activity | J63: =IF(LEN(TRIM(G63))>0,"yes","-") -> yes
A64: H8 | B64: Admin & super-admin | C64: Do your customers administer their own users? | D64: single | E64: yes | F64: one of A3,shared,schema,hybrid | G64: yes | J64: =IF(LEN(TRIM(G64))>0,"yes","-") -> yes
A65: I1 | B65: Authorization model | C65: What does a permission decision actually depend on? | D65: multi | E65: yes | F65: always | G65: role;unit;rel | J65: =IF(LEN(TRIM(G65))>0,"yes","-") -> yes
A66: I2 | B66: Authorization model | C66: Do you need to answer “who can access this record?” and “what can this person access?” as fast queries? | D66: single | E66: yes | F66: always | G66: list | J66: =IF(LEN(TRIM(G66))>0,"yes","-") -> yes
A67: I3 | B67: Authorization model | C67: How do users share things with each other? | D67: single | E67: yes | F67: always | G67: nested | J67: =IF(LEN(TRIM(G67))>0,"yes","-") -> yes
... A75: J5 | B75: Privacy & compliance | C75: How long must core records be kept? | D75: single | E75: yes | F75: always | G75: y6 | J75: =IF(LEN(TRIM(G75))>0,"yes","-") -> yes
A76: J6 | B76: Privacy & compliance | C76: How will you handle children’s data? | D76: single | E76: yes | F76: A2,minor OR A5,child OR A1,edu | J76: =IF(LEN(TRIM(G76))>0,"yes","-") -> -
A77: J7 | B77: Privacy & compliance | C77: Do you understand your breach-notification clock? | D77: single | E77: yes | F77: always | G77: partly | J77: =IF(LEN(TRIM(G77))>0,"yes","-") -> yes
A78: J8 | B78: Privacy & compliance | C78: Do third parties process this data on your behalf? | D78: single | E78: yes | F78: always | G78: few | J78: =IF(LEN(TRIM(G78))>0,"yes","-") -> yes
A79: K1 | B79: Audit & evidence | C79: What must you be able to reconstruct after the fact? | D79: multi | E79: yes | F79: always | G79: authn;change;perm;admin | J79: =IF(LEN(TRIM(G79))>0,"yes","-") -> yes
A80: K2 | B80: Audit & evidence | C80: How long must the audit trail be kept, and how much of it must be instantly searchable? | D80: single | E80: yes | F80: always | G80: y1 | J80: =IF(LEN(TRIM(G80))>0,"yes","-") -> yes
A81: K3 | B81: Audit & evidence | C81: Must the audit trail resist tampering by your own privileged staff? | D81: single | E81: yes | F81: always | G81: offbox | J81: =IF(LEN(TRIM(G81))>0,"yes","-") -> yes
A82: K4 | B82: Audit & evidence | C82: Will you be asked “who had access to this, on this date, and who approved it?” | D82: single | E82: yes | F82: always | G82: routine | J82: =IF(LEN(TRIM(G82))>0,"yes","-") -> yes
A83: L1 | B83: Operations & stack | C83: Who will operate this database? | D83: single | E83: yes | F83: always | G83: small | J83: =IF(LEN(TRIM(G83))>0,"yes","-") -> yes
A84: L2 | B84: Operations & stack | C84: How will it be hosted? | D84: single | E84: yes | F84: always | G84: managed | J84: =IF(LEN(TRIM(G84))>0,"yes","-") -> yes
A85: L3 | B85: Operations & stack | C85: Which platform? | D85: single | E85: yes | F85: always | G85: aws | J85: =IF(LEN(TRIM(G85))>0,"yes","-") -> yes
...

Sheet Conflict checks
A1: # | B1: Severity | C1: Fires? | D1: Finding | E1: Why it matters | F1: What to do | G1: Condition, in plain terms
A2: 1 | B2: Contradiction | C2: =IF(AND(OR(ISNUMBER(SEARCH(";aal2;",";"&INDEX(Answers!$G:$G,MATCH("D1",Answers!$A:$A,0))&";")),ISNUMBER(SEARCH(";aal2p;",";"&INDEX(Answers!$G:$G,MATCH("D1",Answers!$A:$A,0))&";")),ISNUMBER(SEARCH(";aal3;",";"&INDEX(Answers!$G:$G,MATCH("D1",Answers!$A:$A,0))&";"))),OR(ISNUMBER(SEARCH(";emaillink;",";"&INDEX(Answers!$G:$G,MATCH("D4",Answers!$A:$A,0))&";")),ISNUMBER(SEARCH(";sms;",";"&INDEX(Answers!$G:$G,MATCH("D4",Answers!$A:$A,0))&";")))),"FIRES","-") -> - | D2: Your recovery path is weaker than your login path | E2: You require multi-factor authentication to sign in, but a single emailed or texted message is enough to take the account over. An attacker will always choose the weaker route, so your effective assurance level is the recovery path, not the login screen. | F2: Require a second registered authenticator for recovery, or at minimum re-verify to the same strength that was used at registration. The guidance is explicit that email is not a valid out-of-band authentication channel. | G2: Login requires MFA (D1) but recovery is an emailed link or SMS (D4)
A3: 2 | B3: Contradiction | C3: =IF(AND(ISNUMBER(SEARCH(";emailotp;",";"&INDEX(Answers!$G:$G,MATCH("D3",Answers!$A:$A,0))&";")),ISNUMBER(SEARCH(";email;",";"&INDEX(Answers!$G:$G,MATCH("C1",Answers!$A:$A,0))&";"))),"FIRES","-") -> - | D3: Email codes to the account that is the login handle | E3: The login handle is an email address and one of the factors is a code sent to that same address. That is one factor wearing two hats: anyone who reaches the inbox has everything. | F3: Use email links for enrolment and verification, not for authentication. The current guidance states that email SHALL NOT be used for out-of-band authentication. | G3: An email one-time code is a factor (D3) and email is the login handle (C1)
A4: 3 | B4: Risk | C4: =IF(AND(ISNUMBER(SEARCH(";sms;",";"&INDEX(Answers!$G:$G,MATCH("D3",Answers!$A:$A,0))&";")),OR(ISNUMBER(SEARCH(";money;",";"&INDEX(Answers!$G:$G,MATCH("A4",Answers!$A:$A,0))&";")),ISNUMBER(SEARCH(";funds;",";"&INDEX(Answers!$G:$G,MATCH("A5",Answers!$A:$A,0))&";")))),"FIRES","-") -> - | D4: SMS as a factor on a system that moves money | E4: SIM swapping is the standard attack against exactly this configuration, and account-takeover losses tracked through the FBI’s complaint centre are dominated by it. NIST classifies the public telephone network as a restricted channel for this reason. | F4: Keep SMS as a last-resort fallback only, never as sufficient authorisation for a payment, a payout-detail change or a limit change. Require a phishing-resistant factor for those actions. | G4: SMS is a factor (D3) on a system that moves money (A4/A5)
A5: 4 | B5: Risk | C5: =IF(AND(ISNUMBER(SEARCH(";same;",";"&INDEX(Answers!$G:$G,MATCH("D2",Answers!$A:$A,0))&";")),OR(ISNUMBER(SEARCH(";money;",";"&INDEX(Answers!$G:$G,MATCH("A4",Answers!$A:$A,0))&";")),ISNUMBER(SEARCH(";safety;",";"&INDEX(Answers!$G:$G,MATCH("A4",Answers!$A:$A,0))&";")),AND(NOT(ISNUMBER(SEARCH(";none;",";"&INDEX(Answers!$G:$G,MATCH("A5",Answers!$A:$A,0))&";"))),LEN(TRIM(INDEX(Answers!$G:$G,MATCH("A5",Answers!$A:$A,0))))>0))),"FIRES","-") -> - | D5: Administrators authenticate no more strongly than end users | E5: The accounts that can see everything are protected exactly as well as the accounts that can see one record. | F5: Set a separate, higher assurance level for privileged access and a shorter session. The current guidance puts the overall reauthentication timeout at no more than 24 hours at AAL2 (SHOULD, with a 1-hour inactivity timeout) and no more than 12 hours at AAL3 (SHALL, with a 15-minute inactivity timeout). | G5: Admins use the same assurance as users (D2) on a money, safety or regulated system
A6: 5 | B6: Risk | C6: =IF(ISNUMBER(SEARCH(";same;",";"&INDEX(Answers!$G:$G,MATCH("D6",Answers!$A:$A,0))&";")),"FIRES","-") -> - | D6: Administrative sessions last as long as ordinary ones | E6: A privileged session left open on an unattended laptop is the cheapest attack there is. | F6: Cap the administrative session at 12–24 hours absolute with a 15–60 minute idle timeout, and force re-authentication before any dangerous action rather than only at sign-in. | G6: Admin sessions last as long as ordinary sessions (D6)
A7: 6 | B7: Contradiction | C7: =IF(AND(ISNUMBER(SEARCH(";hard;",";"&INDEX(Answers!$G:$G,MATCH("J3",Answers!$A:$A,0))&";")),OR(ISNUMBER(SEARCH(";y6;",";"&INDEX(Answers!$G:$G,MATCH("J5",Answers!$A:$A,0))&";")),ISNUMBER(SEARCH(";y10;",";"&INDEX(Answers!$G:$G,MATCH("J5",Answers!$A:$A,0))&";")),ISNUMBER(SEARCH(";perm;",";"&INDEX(Answers!$G:$G,MATCH("J5",Answers!$A:$A,0))&";")))),"FIRES","-") -> - | D7: Hard deletion contradicts your retention obligation | E7: You have committed to destroying rows on request while also being required to keep records for years. One of these will be breached, and you will not get to choose which. | F7: Replace hard deletion with irreversible anonymisation for retained classes: sever the link to the person, keep the record. Classify every table by retention driver so the rule is executable rather than a matter of judgement at request time. | G7: Hard deletion (J3) with a multi-year retention obligation (J5)
A8: 7 | B8: Contradiction | C8: =IF(AND(ISNUMBER(SEARCH(";no;",";"&INDEX(Answers!$G:$G,MATCH("J3",Answers!$A:$A,0))&";")),OR(ISNUMBER(SEARCH(";gdpr;",";"&INDEX(Answers!$G:$G,MATCH("J1",Answers!$A:$A,0))&";")),ISNUMBER(SEARCH(";ndpa;",";"&INDEX(Answers!$G:$G,MATCH("J1",Answers!$A:$A,0))&";")),ISNUMBER(SEARCH(";kenya;",";"&INDEX(Answers!$G:$G,MATCH("J1",Answers!$A:$A,0))&";")),ISNUMBER(SEARCH(";popia;",";"&INDEX(Answers!$G:$G,MATCH("J1",Answers!$A:$A,0))&";")),ISNUMBER(SEARCH(";afother;",";"&INDEX(Answers!$G:$G,MATCH("J1",Answers!$A:$A,0))&";")),ISNUMBER(SEARCH(";us;",";"&INDEX(Answers!$G:$G,MATCH("J1",Answers!$A:$A,0))&";")))),"FIRES","-") -> - | D8: You are subject to a regime with erasure rights but have no deletion path | E8: A data subject request will arrive and there will be no mechanism to answer it within the statutory window. | F8: Build the request table and the erasure path now. Deciding what “deleted” means per table is the work; the code is small once that decision exists. | G8: No deletion path (J3) under a regime that grants erasure rights (J1)
A9: 8 | B9: Contradiction | C9: =IF(AND(ISNUMBER(SEARCH(";none;",";"&INDEX(Answers!$G:$G,MATCH("J1",Answers!$A:$A,0))&";")),OR(ISNUMBER(SEARCH(";health;",";"&INDEX(Answers!$G:$G,MATCH("C8",Answers!$A:$A,0))&";")),ISNUMBER(SEARCH(";bio;",";"&INDEX(Answers!$G:$G,MATCH("C8",Answers!$A:$A,0))&";")),ISNUMBER(SEARCH(";ethnic;",";"&INDEX(Answers!$G:$G,MATCH("C8",Answers!$A:$A,0))&";")),ISNUMBER(SEARCH(";fin;",";"&INDEX(Answers!$G:$G,MATCH("C8",Answers!$A:$A,0))&";")))),"FIRES","-") -> - | D9: You are storing special-category data but believe no regime applies | E9: Health, biometric, financial and ethnicity data attract heightened obligations almost everywhere they are processed, and the applicable regime follows the data subject, not your registered office. | F9: Establish which regimes apply to each user population before you design the schema. It changes retention, consent evidence, breach clocks and residency. | G9: Special-category attributes selected (C8) but J1 = none
A10: 9 | B10: Risk | C10: =IF(AND(ISNUMBER(SEARCH(";person;",";"&INDEX(Answers!$G:$G,MATCH("H3",Answers!$A:$A,0))&";")),NOT(ISNUMBER(SEARCH(";none;",";"&INDEX(Answers!$G:$G,MATCH("H5",Answers!$A:$A,0))&";"))),LEN(TRIM(INDEX(Answers!$G:$G,MATCH("H5",Answers!$A:$A,0))))>0),"FIRES","-") -> - | D10: A standing super-administrator defeats your own approval rules | E10: You require a second approver for some actions while also keeping an account that can do anything. Whoever holds that account is a single point of both failure and compromise. | F10: Convert the super-administrator into a break-glass role that must be assumed, is time-boxed, alerts on assumption, and is reviewed afterwards. No standing total power. | G10: A standing super-admin (H3) alongside second-approver requirements (H5)
A11: 10 | B11: Contradiction | C11: =IF(AND(ISNUMBER(SEARCH(";any;",";"&INDEX(Answers!$G:$G,MATCH("H2",Answers!$A:$A,0))&";")),OR(ISNUMBER(SEARCH(";maker;",";"&INDEX(Answers!$G:$G,MATCH("G5",Answers!$A:$A,0))&";")),ISNUMBER(SEARCH(";iam;",";"&INDEX(Answers!$G:$G,MATCH("G5",Answers!$A:$A,0))&";")),ISNUMBER(SEARCH(";refund;",";"&INDEX(Answers!$G:$G,MATCH("G5",Answers!$A:$A,0))&";")),ISNUMBER(SEARCH(";publish;",";"&INDEX(Answers!$G:$G,MATCH("G5",Answers!$A:$A,0))&";")),ISNUMBER(SEARCH(";vendor;",";"&INDEX(Answers!$G:$G,MATCH("G5",Answers!$A:$A,0))&";")),ISNUMBER(SEARCH(";stock;",";"&INDEX(Answers!$G:$G,MATCH("G5",Answers!$A:$A,0))&";")),ISNUMBER(SEARCH(";clinical;",";"&INDEX(Answers!$G:$G,MATCH("G5",Answers!$A:$A,0))&";")),ISNUMBER(SEARCH(";grade;",";"&INDEX(Answers!$G:$G,MATCH("G5",Answers!$A:$A,0))&";")))),"FIRES","-") -> - | D11: Separation of duties cannot hold if any administrator can grant any role | E11: Any administrator can grant themselves the other half of a separated duty in one click, and the audit trail will show a legitimate grant followed by a legitimate action. | F11: Add a grant ceiling — an administrator may only grant what they hold, or only roles explicitly listed as grantable — and check separation constraints at grant time, not only at review time. | G11: Any admin can grant any role (H2) while duties must be separated (G5)
A12: 11 | B12: Risk | C12: =IF(ISNUMBER(SEARCH(";unrestricted;",";"&INDEX(Answers!$G:$G,MATCH("H4",Answers!$A:$A,0))&";")),"FIRES","-") -> - | D12: Impersonation with no ceremony | E12: Actions taken while impersonating are indistinguishable from actions taken by the user. When a customer disputes something, you will have no way to answer. | F12: Require a reason, cap the session, log to both the audit trail and the user’s own security log, and notify the user without an option to suppress it. That combination is the established pattern. | G12: Impersonation with no ceremony (H4 = unrestricted)
A13: 12 | B13: Risk | C13: =IF(AND(NOT(OR(ISNUMBER(SEARCH(";no;",";"&INDEX(Answers!$G:$G,MATCH("H4",Answers!$A:$A,0))&";")),ISNUMBER(SEARCH(";readonly;",";"&INDEX(Answers!$G:$G,MATCH("H4",Answers!$A:$A,0))&";")))),NOT(ISNUMBER(SEARCH(";imperson;",";"&INDEX(Answers!$G:$G,MATCH("K1",Answers!$A:$A,0))&";")))),"FIRES","-") -> - | D13: Impersonation is enabled but not separately audited | E13: A single actor column cannot distinguish “the user did this” from “support did this as the user”. | F13: Add a second actor column to every audited event and record the impersonation session id alongside it. | G13: Write impersonation enabled (H4) but not separately audited (K1)
A14: 13 | B14: Contradiction | C14: =IF(AND(ISNUMBER(SEARCH(";eventual;",";"&INDEX(Answers!$G:$G,MATCH("B9",Answers!$A:$A,0))&";")),OR(ISNUMBER(SEARCH(";money;",";"&INDEX(Answers!$G:$G,MATCH("A4",Answers!$A:$A,0))&";")),ISNUMBER(SEARCH(";funds;",";"&INDEX(Answers!$G:$G,MATCH("A5",Answers!$A:$A,0))&";")))),"FIRES","-") -> - | D14: Eventual consistency on a path that moves money | E14: Double-spend, duplicated payouts and lost updates are the normal outcome, and they surface as reconciliation breaks weeks later rather than as errors at the time. | F14: Keep the money path strictly transactional in a single-writer engine. Use eventual consistency for derived views and read models only. | G14: Eventual consistency (B9) on a money path (A4/A5)
A15: 14 | B15: Contradiction | C15: =IF(ISNUMBER(SEARCH(";balance;",";"&INDEX(Answers!$G:$G,MATCH("X-FIN1",Answers!$A:$A,0))&";")),"FIRES","-") -> - | D15: A mutable balance column is not an accounting system | E15: Overwriting a balance destroys the only evidence of how it got there. You cannot reconcile, you cannot answer a dispute, and you cannot reconstruct a position as at a past date. | F15: Use an immutable double-entry ledger and derive balances, optionally materialising them for speed. Every movement is two entries and no entry is ever updated. | G15: Money represented as a mutable balance column (X-FIN1)
A16: 15 | B16: Risk | C16: =IF(AND(ISNUMBER(SEARCH(";auto;",";"&INDEX(Answers!$G:$G,MATCH("L8",Answers!$A:$A,0))&";")),NOT(ISNUMBER(SEARCH(";weeks;",";"&INDEX(Answers!$G:$G,MATCH("L10",Answers!$A:$A,0))&";")))),"FIRES","-") -> - | D16: Automatic schema synchronisation is not a migration strategy | E16: It cannot express a backfill, a rename, a concurrent index build, or a rollback — and it will happily drop a column in production. | F16: Move to reviewed migration files with an explicit rollback path before your first production deployment. | G16: Automatic schema sync (L8) outside a weeks-long throwaway timeline (L10)
A17: 16 | B17: Contradiction | C17: =IF(AND(ISNUMBER(SEARCH(";sub1;",";"&INDEX(Answers!$G:$G,MATCH("I5",Answers!$A:$A,0))&";")),ISNUMBER(SEARCH(";svc;",";"&INDEX(Answers!$G:$G,MATCH("I6",Answers!$A:$A,0))&";"))),"FIRES","-") -> - | D17: A network policy service cannot meet a sub-millisecond budget | E17: One network round trip alone exceeds your stated budget, before the policy is evaluated. | F17: Either evaluate in-process against a locally cached, version-stamped decision set, or push the decision into the database as a row filter. Keep the policy service for management and distribution, not for the hot path. | G17: Sub-millisecond check budget (I5) with a network policy service (I6)
A18: 17 | B18: Consider | C18: =IF(AND(NOT(ISNUMBER(SEARCH(";no;",";"&INDEX(Answers!$G:$G,MATCH("I4",Answers!$A:$A,0))&";"))),LEN(TRIM(INDEX(Answers!$G:$G,MATCH("I4",Answers!$A:$A,0))))>0,NOT(OR(ISNUMBER(SEARCH(";rel;",";"&INDEX(Answers!$G:$G,MATCH("I1",Answers!$A:$A,0))&";")),ISNUMBER(SEARCH(";assign;",";"&INDEX(Answers!$G:$G,MATCH("I1",Answers!$A:$A,0))&";")),ISNUMBER(SEARCH(";nested;",";"&INDEX(Answers!$G:$G,MATCH("I3",Answers!$A:$A,0))&";")))),NOT(OR(ISNUMBER(SEARCH(";attr;",";"&INDEX(Answers!$G:$G,MATCH("I1",Answers!$A:$A,0))&";")),ISNUMBER(SEARCH(";state;",";"&INDEX(Answers!$G:$G,MATCH("I1",Answers!$A:$A,0))&";")),ISNUMBER(SEARCH(";clear;",";"&INDEX(Answers!$G:$G,MATCH("I1",Answers!$A:$A,0))&";")),ISNUMBER(SEARCH(";consent;",";"&INDEX(Answers!$G:$G,MATCH("I1",Answers!$A:$A,0))&";")))),OR(ISNUMBER(SEARCH(";r1;",";"&INDEX(Answers!$G:$G,MATCH("G1",Answers!$A:$A,0))&";")),ISNUMBER(SEARCH(";r2;",";"&INDEX(Answers!$G:$G,MATCH("G1",Answers!$A:$A,0))&";"))),ISNUMBER(SEARCH(";global;",";"&INDEX(Answers!$G:$G,MATCH("G3",Answers!$A:$A,0))&";"))),"FIRES","-") -> - | D18: You need denies, but you have chosen the one model that has none | E18: The role-based standard defines no negative permissions. Denies bolted onto a pure role model as ordered rules become unreviewable quickly. | F18: Keep grants purely additive and put denies in a separate, last-evaluated layer where deny always wins and order never matters. | G18: Denies required (I4) under a pure core-RBAC configuration (G1/G3)
A19: 18 | B19: Risk | C19: =IF(AND(ISNUMBER(SEARCH(";append;",";"&INDEX(Answers!$G:$G,MATCH("K3",Answers!$A:$A,0))&";")),OR(ISNUMBER(SEARCH(";routine;",";"&INDEX(Answers!$G:$G,MATCH("K4",Answers!$A:$A,0))&";")),ISNUMBER(SEARCH(";contract;",";"&INDEX(Answers!$G:$G,MATCH("K4",Answers!$A:$A,0))&";")))),"FIRES","-") -> - | D19: Application-level append-only will not satisfy an auditor | E19: In PostgreSQL a table owner is always treated as holding all grant options, so an append-only trigger constrains application bugs, not privileged people. | F19: Ship audit records to storage controlled by a different set of credentials. That is the control that survives the question “who could have altered this?”. | G19: Application-level append-only audit (K3) with routine external scrutiny (K4)
A20: 19 | B20: Risk | C20: =IF(ISNUMBER(SEARCH(";natid;",";"&INDEX(Answers!$G:$G,MATCH("C1",Answers!$A:$A,0))&";")),"FIRES","-") -> - | D20: A national ID or licence number is an identifier, not a credential | E20: These numbers are widely known, often printed on documents, and cannot be rotated when they leak. Using one as the login handle means the account name is public and permanent. | F20: Store it as a verified attribute with its own access controls, and issue a separate account identifier. The US federal rule for driver logs takes exactly this position: the record is anchored to the licence, but the licence number must not be the account identifier. | G20: A national ID or licence number used as a login handle (C1)
A21: 20 | B21: Risk | C21: =IF(ISNUMBER(SEARCH(";unsure;",";"&INDEX(Answers!$G:$G,MATCH("A3",Answers!$A:$A,0))&";")),"FIRES","-") -> - | D21: Multi-tenancy is still undecided | E21: This is the one decision that is genuinely expensive to reverse: adding a tenant column to a live schema means touching every table, every index, every query and every cached decision. | F21: Add tenant_id everywhere now, even at one tenant. It costs a column today and saves a quarter later. | G21: Multi-tenancy undecided (A3)
A22: 21 | B22: Risk | C22: =IF(AND(ISNUMBER(SEARCH(";minor;",";"&INDEX(Answers!$G:$G,MATCH("A2",Answers!$A:$A,0))&";")),NOT(LEN(TRIM(INDEX(Answers!$G:$G,MATCH("J6",Answers!$A:$A,0))))>0)),"FIRES","-") -> - | D22: Under-18 users, with no stated approach to children’s data | E22: Almost every regime imposes additional conditions for children — a lower age of consent, verifiable parental consent, restrictions on profiling. | F22: Decide now whether you block, obtain verifiable parental consent, or rely on an institution’s lawful basis. It changes the registration flow and the schema. | G22: Under-18 users (A2) with no answer to the children-data question (J6)
A23: 22 | B23: Risk | C23: =IF(AND(OR(ISNUMBER(SEARCH(";large;",";"&INDEX(Answers!$G:$G,MATCH("B1",Answers!$A:$A,0))&";")),ISNUMBER(SEARCH(";huge;",";"&INDEX(Answers!$G:$G,MATCH("B1",Answers!$A:$A,0))&";"))),ISNUMBER(SEARCH(";solo;",";"&INDEX(Answers!$G:$G,MATCH("L1",Answers!$A:$A,0))&";"))),"FIRES","-") -> - | D23: Data volume and operational capacity are mismatched | E23: You are planning for hundreds of millions to billions of rows with one or two generalist developers and no database specialist. | F23: Reduce the operational surface: one managed database, partitioning from day one, and no additional stores until a measurement forces one. Every extra system costs a person you do not have. | G23: Large or huge data volume (B1) with a single generalist developer (L1)
A24: 23 | B24: Risk | C24: =IF(AND(ISNUMBER(SEARCH(";no;",";"&INDEX(Answers!$G:$G,MATCH("H6",Answers!$A:$A,0))&";")),OR(ISNUMBER(SEARCH(";routine;",";"&INDEX(Answers!$G:$G,MATCH("K4",Answers!$A:$A,0))&";")),ISNUMBER(SEARCH(";contract;",";"&INDEX(Answers!$G:$G,MATCH("K4",Answers!$A:$A,0))&";")))),"FIRES","-") -> - | D24: Auditors will ask for access reviews you are not producing | E24: Recertification evidence is a point-in-time snapshot with a signed decision per line. It cannot be reconstructed from live tables afterwards, because the live tables only show the current state. | F24: Run scheduled campaigns that snapshot the grants under review and record an explicit decision and reviewer per line. | G24: No access reviews (H6) with routine or contractual access questions (K4)
A25: 24 | B25: Risk | C25: =IF(ISNUMBER(SEARCH(";pan;",";"&INDEX(Answers!$G:$G,MATCH("E4",Answers!$A:$A,0))&";")),"FIRES","-") -> - | D25: Storing card numbers puts your entire environment in scope | E25: Everything that stores, processes or transmits card data — and everything connected to it — falls inside the assessed environment. | F25: Unless you are building a payment processor, use a provider’s hosted fields or tokenisation so the number never reaches your systems. This is the single largest scope reduction available to you. | G25: Raw card numbers stored (E4)
A26: 25 | B26: Risk | C26: =IF(AND(NOT(ISNUMBER(SEARCH(";delete;",";"&INDEX(Answers!$G:$G,MATCH("E1",Answers!$A:$A,0))&";"))),OR(ISNUMBER(SEARCH(";gdpr;",";"&INDEX(Answers!$G:$G,MATCH("J1",Answers!$A:$A,0))&";")),ISNUMBER(SEARCH(";ndpa;",";"&INDEX(Answers!$G:$G,MATCH("J1",Answers!$A:$A,0))&";")),ISNUMBER(SEARCH(";kenya;",";"&INDEX(Answers!$G:$G,MATCH("J1",Answers!$A:$A,0))&";")),ISNUMBER(SEARCH(";popia;",";"&INDEX(Answers!$G:$G,MATCH("J1",Answers!$A:$A,0))&";")),ISNUMBER(SEARCH(";afother;",";"&INDEX(Answers!$G:$G,MATCH("J1",Answers!$A:$A,0))&";")),ISNUMBER(SEARCH(";us;",";"&INDEX(Answers!$G:$G,MATCH("J1",Answers!$A:$A,0))&";")))),"FIRES","-") -> - | D26: No account deletion, under a regime that grants deletion rights | E26: You will receive the request regardless of whether you built the button. | F26: Build the request path even if the outcome is anonymisation rather than destruction. What matters is that the request is received, tracked against its statutory deadline, and answered. | G26: No account deletion feature (E1) under an erasure regime (J1)
A27: 26 | B27: Risk | C27: =IF(AND(NOT(ISNUMBER(SEARCH(";consent;",";"&INDEX(Answers!$G:$G,MATCH("E1",Answers!$A:$A,0))&";"))),OR(ISNUMBER(SEARCH(";purpose;",";"&INDEX(Answers!$G:$G,MATCH("J2",Answers!$A:$A,0))&";")),ISNUMBER(SEARCH(";versioned;",";"&INDEX(Answers!$G:$G,MATCH("J2",Answers!$A:$A,0))&";")))),"FIRES","-") -> - | D27: Per-purpose consent with no way for a user to withdraw it | E27: Withdrawal must be as easy as giving consent. If consent was collected in a checkbox and withdrawal requires an email to support, that test is not met. | F27: Add a preference centre that writes a withdrawal event to the same log the original consent was written to. | G27: Per-purpose consent (J2) with no consent centre in the product (E1)
A28: 27 | B28: Consider | C28: =IF(AND(ISNUMBER(SEARCH(";idp;",";"&INDEX(Answers!$G:$G,MATCH("G2",Answers!$A:$A,0))&";")),ISNUMBER(SEARCH(";catalog;",";"&INDEX(Answers!$G:$G,MATCH("H1",Answers!$A:$A,0))&";"))),"FIRES","-") -> - | D28: Two sources of truth for roles | E28: Roles arrive from the identity provider and can also be edited in your application. Whichever was changed last wins, and nobody can tell which that was. | F28: Decide which system is authoritative. If it is the identity provider, make in-app roles read-only and record the mapping; if it is your application, stop importing role claims and use the provider for authentication only. | G28: Roles arrive from the IdP (G2) and are also editable in-app (H1)
A29: 28 | B29: Contradiction | C29: =IF(AND(ISNUMBER(SEARCH(";current;",";"&INDEX(Answers!$G:$G,MATCH("F3",Answers!$A:$A,0))&";")),OR(ISNUMBER(SEARCH(";routine;",";"&INDEX(Answers!$G:$G,MATCH("K4",Answers!$A:$A,0))&";")),ISNUMBER(SEARCH(";contract;",";"&INDEX(Answers!$G:$G,MATCH("K4",Answers!$A:$A,0))&";")))),"FIRES","-") -> - | D29: You will be asked to reconstruct a past state you are not recording | E29: “Who managed this branch in March?” cannot be answered from current-state tables, and the history you did not record cannot be recovered later. | F29: Add validity periods to assignments, memberships and edges now. This is the least reversible omission in the whole design. | G29: Current-state-only structure (F3) with routine point-in-time questions (K4)
A30: 29 | B30: Consider | C30: =IF(AND(ISNUMBER(SEARCH(";full;",";"&INDEX(Answers!$G:$G,MATCH("B10",Answers!$A:$A,0))&";")),OR(ISNUMBER(SEARCH(";own;",";"&INDEX(Answers!$G:$G,MATCH("G3",Answers!$A:$A,0))&";")),ISNUMBER(SEARCH(";inherit;",";"&INDEX(Answers!$G:$G,MATCH("G3",Answers!$A:$A,0))&";")),ISNUMBER(SEARCH(";explicit;",";"&INDEX(Answers!$G:$G,MATCH("G3",Answers!$A:$A,0))&";")),ISNUMBER(SEARCH(";object;",";"&INDEX(Answers!$G:$G,MATCH("G3",Answers!$A:$A,0))&";")))),"FIRES","-") -> - | D30: Offline clients need permissions that can go stale safely | E30: A cached permission set is a decision made at a past moment. Without a version stamp you cannot tell how stale it is, and a revocation may never reach the device. | F30: Stamp every cached decision with a permissions version and a fetch time, enforce a maximum staleness, and re-check dangerous actions online before allowing them. | G30: Offline clients (B10) with scoped permissions (G3)
A31: 30 | B31: Consider | C31: =IF(IF(LEN(TRIM(INDEX(Answers!$G:$G,MATCH("C8",Answers!$A:$A,0))))=0,0,LEN(INDEX(Answers!$G:$G,MATCH("C8",Answers!$A:$A,0)))-LEN(SUBSTITUTE(INDEX(Answers!$G:$G,MATCH("C8",Answers!$A:$A,0)),";",""))+1)>6,"FIRES","-") -> - | D31: You are collecting a lot of personal data | E31: Every attribute here is something you must secure, retain to a schedule, disclose on request, and report if breached. The cheapest personal data to protect is the kind you never collected. | F31: For each attribute, name the specific feature that reads it today. Anything you cannot name, remove from the schema before launch. | G31: More than six categories of personal attribute selected (C8)
A32: 31 | B32: Consider | C32: =IF(AND(ISNUMBER(SEARCH(";exact;",";"&INDEX(Answers!$G:$G,MATCH("C9",Answers!$A:$A,0))&";")),NOT(ISNUMBER(SEARCH(";child;",";"&INDEX(Answers!$G:$G,MATCH("A5",Answers!$A:$A,0))&";"))),NOT(ISNUMBER(SEARCH(";fintech;",";"&INDEX(Answers!$G:$G,MATCH("A1",Answers!$A:$A,0))&";"))),NOT(ISNUMBER(SEARCH(";health;",";"&INDEX(Answers!$G:$G,MATCH("A1",Answers!$A:$A,0))&";")))),"FIRES","-") -> - | D32: An exact date of birth where an age band would do | E32: A birth date is a strong identifier and a common knowledge-based-authentication answer. An age band answers most product questions and identifies nobody. | F32: Verify once, store the band, discard the date — unless a rule genuinely depends on the exact day. | G32: Exact date of birth (C9) with no rule that needs the exact day

Sheet Decision rules
A1: # | B1: Decision area | C1: Condition | D1: Primary recommendation | E1: Alternative | F1: Switch when | G1: Evidence
A2: 1 | B2: Primary datastore | C2: B10 = full offline writes | D2: PostgreSQL on the server + SQLite on each device, with an explicit versioned sync protocol | E2: A sync-first platform (ElectricSQL, PowerSync, CouchDB/PouchDB) | F2: Switch to a sync platform once hand-rolled conflict resolution passes a few hundred lines, or two clients can legitimately edit the same row | G2: PG-DOCS / SQLITE
A3: 2 | B3: Primary datastore | C3: L2 = serverless runtime | D3: Serverless-native managed PostgreSQL (Neon, Aurora Serverless v2, Cloud SQL/AlloyDB) behind a pooler | E3: Provider-native store (DynamoDB, Firestore, D1) | F3: Only if access patterns are genuinely key-value and you will never need a join, a report or a foreign key | G3: PG-DOCS
A4: 3 | B4: Primary datastore | C4: B1 = tiny AND A3 = single AND B3 = <100 concurrent AND not regulated AND one country | D4: PostgreSQL 18 | E4: SQLite in WAL mode, embedded | F4: SQLite stops being viable at a second writing app node, a network filesystem, or per-role row filtering in the database | G4: SQLITE
A5: 4 | B5: Primary datastore | C5: B5 = polymorphic AND money is not involved | D5: PostgreSQL with jsonb for the variable part, columns for the stable part | E5: MongoDB | F5: Move to a document store when under ~40% of fields are shared across records AND no query ever relates two record types | G5: MONGO
A6: 5 | B6: Primary datastore | C6: B6 = global AND L4 >= 99.95% AND money/strict consistency | D6: PostgreSQL 18 | E6: Distributed SQL (CockroachDB, YugabyteDB, Spanner) | F6: When a single write region cannot meet latency in a second region, or regional write outage becomes commercially unacceptable | G6: PG-DOCS
A7: 6 | B7: Primary datastore | C7: B1 in (large, huge) AND B4 = dominant event stream | D7: PostgreSQL 18 for entities | E7: PostgreSQL + ClickHouse for the event stream | F7: Split when the event table alone passes ~1 billion rows, or analytical scans interfere with transactional latency | G7: CLICKHOUSE
A8: 7 | B8: Primary datastore | C8: Default | D8: PostgreSQL 18 | E8: Managed MySQL 8.4 LTS | F8: Only for an existing-expertise or existing-platform reason; no capability in this matrix is MySQL-only, and several are PostgreSQL-only | G8: PG-DOCS
A9: 8 | B9: Tenancy | C9: A3 = single | D9: One dataset, but with an organisational scope column from day one | E9: Add tenant_id anyway | F9: Add tenant_id now if any commercial scenario has a second organisation using the system | G9: PG-RLS
A10: 9 | B10: Tenancy | C10: A3 = schema-per-tenant | D10: Schema-per-tenant on one cluster; route by search_path at checkout | E10: Shared schema + tenant_id + RESTRICTIVE RLS | F10: Move to shared past roughly 500-1,000 tenants: migrations become N-schema batch jobs and catalogue overhead dominates | G10: PG-RLS
A11: 10 | B11: Tenancy | C11: A3 in (shared, hybrid, unsure) | D11: Shared schema, tenant_id on every row, RESTRICTIVE RLS with FORCE, tenant read as (SELECT fn()) for InitPlan hoisting | E11: Dedicated database for named large customers, chosen by a placement lookup | F11: Split a tenant at ~100x median size or on a contractual isolation requirement; build the placement indirection first | G11: PG-RLS / SUPABASE
A12: 11 | B12: Search | C12: B7 = prefix/substring | D12: PostgreSQL B-tree + pg_trgm GIN | E12: A dedicated search engine | F12: When relevance ordering, not matching, becomes the complaint | G12: PG-DOCS
A13: 12 | B13: Search | C13: B7 = ranked full text | D13: PostgreSQL tsvector + GIN on a generated column | E13: OpenSearch / Elasticsearch / Typesense via CDC | F13: Past roughly 5 million documents, or when synonyms, per-tenant tuning or multi-dimension faceting are required | G13: PG-DOCS
... A75: 74 | B75: Domain-specific requirements | C75: G9 = contractor expiry / sponsor | D75: Mandatory end date on contractor grants; sponsor_id + scheduled re-attestation | E75: Open-ended grants | F75: Nobody knows who the account belongs to any more | G75: NIST-53

Sheet Question bank
A1: Question | B1: Section | C1: Question text | D1: Answer code | E1: Answer label | F1: Clarification
A2: A1 | B2: Domain & risk | C2: Which best describes what the system is for? | D2: fintech | E2: Financial services — banking, payments, lending, wallets | F2: You hold, move or lend other people’s money.
A3: A1 | B3: Domain & risk | C3: Which best describes what the system is for? | D3: health | E3: Healthcare or clinical | F3: Patient records, care delivery, diagnostics, telehealth.
A4: A1 | B4: Domain & risk | C4: Which best describes what the system is for? | D4: b2bsaas | E4: B2B SaaS sold to organisations | F4: Your customers are companies whose employees are your users.
A5: A1 | B5: Domain & risk | C5: Which best describes what the system is for? | D5: commerce | E5: Commerce, marketplace or retail | F5: Catalogue, orders, payments, fulfilment, possibly physical stores.
A6: A1 | B6: Domain & risk | C6: Which best describes what the system is for? | D6: logistics | E6: Logistics, field service or fleet | F6: Drivers, technicians, warehouses, routes, devices in the field.
A7: A1 | B7: Domain & risk | C7: Which best describes what the system is for? | D7: edu | E7: Education | F7: Schools, universities, training providers, LMS.
A8: A1 | B8: Domain & risk | C8: Which best describes what the system is for? | D8: gov | E8: Government or public sector | F8: Citizen services, licensing, records, statutory duties.
A9: A1 | B9: Domain & risk | C9: Which best describes what the system is for? | D9: internal | E9: Internal enterprise tool | F9: Used only by your own staff; no external customers.
A10: A1 | B10: Domain & risk | C10: Which best describes what the system is for? | D10: social | E10: Consumer social, content or community | F10: User-generated content, feeds, messaging, moderation.
A11: A1 | B11: Domain & risk | C11: Which best describes what the system is for? | D11: devtool | E11: Developer or infrastructure tooling | F11: APIs, CI, observability, data platforms.
A12: A1 | B12: Domain & risk | C12: Which best describes what the system is for? | D12: other | E12: Other - specify | F12: Free text; recorded verbatim in the brief and flagged for a human decision.
... A36: A5 | B36: Domain & risk | C36: Does the system do any of these regulated things? | D36: card | E36: Touches raw payment-card numbers (PAN) | F36: Only if the PAN enters your systems. Hosted fields / tokenisation means no.
A37: A5 | B37: Domain & risk | C37: Does the system do any of these regulated things? | D37: phi | E37: Stores health or medical information
A38: A5 | B38: Domain & risk | C38: Does the system do any of these regulated things? | D38: child | E38: Knowingly collects data from children
A39: A5 | B39: Domain & risk | C39: Does the system do any of these regulated things? | D39: bio | E39: Processes biometrics (face, fingerprint, voice) | F39: Special-category data in most regimes; some US states require separate consent.
A40: A5 | B40: Domain & risk | C40: Does the system do any of these regulated things? | D40: credit | E40: Makes automated credit, insurance or eligibility decisions | F40: Triggers automated-decision and explainability duties.
A41: A5 | B41: Domain & risk | C41: Does the system do any of these regulated things? | D41: gov | E41: Maintains official or public records | F41: Statutory retention schedules, disclosure regimes.
A42: A5 | B42: Domain & risk | C42: Does the system do any of these regulated things? | D42: crypto | E42: Deals in crypto-assets or virtual currency
A43: A5 | B43: Domain & risk | C43: Does the system do any of these regulated things? | D43: none | E43: None of the above
A44: A5 | B44: Domain & risk | C44: Does the system do any of these regulated things? | D44: other | E44: Other - specify | F44: Free text; recorded verbatim in the brief and flagged for a human decision.
A45: B1 | B45: Scale & data shape | C45: How many rows will your largest single table hold 24 months after launch? | D45: tiny | E45: Under 1 million
A46: B1 | B46: Scale & data shape | C46: How many rows will your largest single table hold 24 months after launch? | D46: small | E46: 1 – 50 million
A47: B1 | B47: Scale & data shape | C47: How many rows will your largest single table hold 24 months after launch? | D47: mid | E47: 50 – 500 million
A48: B1 | B48: Scale & data shape | C48: How many rows will your largest single table hold 24 months after launch? | D48: large | E48: 500 million – 5 billion
A49: B1 | B49: Scale & data shape | C49: How many rows will your largest single table hold 24 months after launch? | D49: huge | E49: Over 5 billion
A50: B1 | B50: Scale & data shape | C50: How many rows will your largest single table hold 24 months after launch? | D50: unk | E50: Genuinely unknown | F50: Fine. It will be treated as “small” with a re-check trigger.
A51: B1 | B51: Scale & data shape | C51: How many rows will your largest single table hold 24 months after launch? | D51: other | E51: Other - specify | F51: Free text; recorded verbatim in the brief and flagged for a human decision.
A52: B2 | B52: Scale & data shape | C52: What is the read-to-write ratio on the busiest path? | D52: readheavy | E52: Overwhelmingly reads (95%+) | F52: Catalogues, content, dashboards.
A53: B2 | B53: Scale & data shape | C53: What is the read-to-write ratio on the busiest path? | D53: balanced | E53: Mixed — roughly 70:30 to 50:50
A54: B2 | B54: Scale & data shape | C54: What is the read-to-write ratio on the busiest path? | D54: writeheavy | E54: Write-heavy — ingest dominates | F54: Telemetry, events, tracking, IoT.
A55: B2 | B55: Scale & data shape | C55: What is the read-to-write ratio on the busiest path? | D55: bursty | E55: Quiet, punctuated by extreme bursts | F55: Ticket sales, results days, paydays, flash sales.
A56: B2 | B56: Scale & data shape | C56: What is the read-to-write ratio on the busiest path? | D56: other | E56: Other - specify | F56: Free text; recorded verbatim in the brief and flagged for a human decision.
A57: B3 | B57: Scale & data shape | C57: Peak concurrent active users or connections at the busiest minute? | D57: p1 | E57: Under 100
A58: B3 | B58: Scale & data shape | C58: Peak concurrent active users or connections at the busiest minute? | D58: p2 | E58: 100 – 2,000
A59: B3 | B59: Scale & data shape | C59: Peak concurrent active users or connections at the busiest minute? | D59: p3 | E59: 2,000 – 20,000
A60: B3 | B60: Scale & data shape | C60: Peak concurrent active users or connections at the busiest minute? | D60: p4 | E60: 20,000 – 200,000
A61: B3 | B61: Scale & data shape | C61: Peak concurrent active users or connections at the busiest minute? | D61: p5 | E61: Over 200,000
A62: B3 | B62: Scale & data shape | C62: Peak concurrent active users or connections at the busiest minute? | D62: other | E62: Other - specify | F62: Free text; recorded verbatim in the brief and flagged for a human decision.
A63: B4 | B63: Scale & data shape | C63: Does the dominant data have a time axis — is it a stream of dated events? | D63: dominant | E63: Yes — the main table is an append-only event or transaction log
...

Sheet Role matrix
A1: Permission key | B1: Action | C1: Resource | D1: Description | E1: Dangerous? | F1: Viewer | G1: Member | H1: Administrator | I1: Billing Manager | J1: Security Admin | K1: Access Admin | L1: Break Glass | M1: Granted to
A2: user.read | B2: read | C2: user | D2: View user records | E2: - | F2: X | H2: X | K2: X | L2: X | M2: =COUNTIF(F2:L2,"X") -> 4
A3: user.create | B3: create | C3: user | D3: Create user accounts | E3: - | H3: X | L3: X | M3: =COUNTIF(F3:L3,"X") -> 2
A4: user.suspend | B4: suspend | C4: user | D4: Suspend a user account | E4: YES | H4: X | L4: X | M4: =COUNTIF(F4:L4,"X") -> 2
A5: user.impersonate | B5: impersonate | C5: user | D5: Act on behalf of a user | E5: YES | L5: X | M5: =COUNTIF(F5:L5,"X") -> 1
A6: role.read | B6: read | C6: role | D6: View roles and assignments | E6: - | F6: X | H6: X | J6: X | K6: X | L6: X | M6: =COUNTIF(F6:L6,"X") -> 5
A7: role.grant | B7: grant | C7: role | D7: Assign a role to a principal | E7: YES | K7: X | L7: X | M7: =COUNTIF(F7:L7,"X") -> 2
A8: role.define | B8: define | C8: role | D8: Create or edit custom roles | E8: YES | K8: X | L8: X | M8: =COUNTIF(F8:L8,"X") -> 2
A9: org.read | B9: read | C9: org_node | D9: View the organisation tree | E9: - | F9: X | H9: X | L9: X | M9: =COUNTIF(F9:L9,"X") -> 3
A10: org.manage | B10: manage | C10: org_node | D10: Create, rename or close org nodes | E10: YES | H10: X | L10: X | M10: =COUNTIF(F10:L10,"X") -> 2
A11: staff.read | B11: read | C11: staff | D11: View staff records | E11: - | F11: X | H11: X | L11: X | M11: =COUNTIF(F11:L11,"X") -> 3
A12: staff.assign | B12: assign | C12: staff | D12: Assign staff to branches or departments | E12: - | H12: X | L12: X | M12: =COUNTIF(F12:L12,"X") -> 2
A13: audit.read | B13: read | C13: audit | D13: Read the security audit log | E13: YES | J13: X | L13: X | M13: =COUNTIF(F13:L13,"X") -> 2
A14: consent.read | B14: read | C14: consent | D14: View consent records | E14: - | H14: X | L14: X | M14: =COUNTIF(F14:L14,"X") -> 2
A15: privacy.fulfil_request | B15: fulfil | C15: subject_request | D15: Fulfil a data subject request | E15: YES | L15: X | M15: =COUNTIF(F15:L15,"X") -> 1
A16: approval.approve | B16: approve | C16: approval | D16: Approve a pending request | E16: YES | H16: X | L16: X | M16: =COUNTIF(F16:L16,"X") -> 2
A17: billing.read | B17: read | C17: billing | D17: View billing information | E17: - | I17: X | L17: X | M17: =COUNTIF(F17:L17,"X") -> 2
A18: billing.manage | B18: manage | C18: billing | D18: Change payment methods and plans | E18: YES | I18: X | L18: X | M18: =COUNTIF(F18:L18,"X") -> 2
A19: security.manage | B19: manage | C19: security | D19: Manage security settings and policy | E19: YES | J19: X | L19: X | M19: =COUNTIF(F19:L19,"X") -> 2
A21: The deliberate gaps are the point.
A22: Access Admin can grant roles but CANNOT read the audit log. Security Admin reads the audit log but CANNOT grant roles. That split is NIST SP 800-53 AC-5: personnel who administer access control functions do not also administer audit functions. Collapsing them into one "admin" role is the single most common privilege-design error.
A23: Billing is separated from operational administration. Every mature product examined for this matrix (GitHub, Slack, Notion, Stripe) separates who pays from who administers; products built without the pattern almost never do.
A24: Break Glass holds everything - and is therefore a role that must be assumed with a reason, a time limit and an alert, never a standing assignment and never a boolean column on a user row.
A25: Member holds no permissions in this table because a member's rights come from relationships to objects, not from the role. If your Member row fills up, you are modelling relationship-based access as roles.
A26: No permission here is granted by more than one role by accident. Check the "Granted to" count whenever you add a role: a permission held by five roles is usually a permission that should have been split.

Sheet Regime clocks
A1: Regime | B1: Instrument | C1: Notify the authority within | D1: Notify the data subject within | E1: Erasure right | F1: Residency / transfer | G1: Retention | H1: Consent / lawful basis
A2: EU GDPR / UK GDPR | B2: Regulation (EU) 2016/679; UK GDPR + DPA 2018 | C2: Without undue delay and, where feasible, no later than 72 hours after becoming aware (Art. 33) | D2: Without undue delay where risk to rights and freedoms is high (Art. 34) | E2: Yes - Art. 17, subject to Art. 17(3) exemptions (legal obligation, legal claims, public interest) | F2: No general localisation. Transfers outside the EEA/UK need an Art. 46 mechanism or an adequacy decision. | G2: Art. 5(1)(e) storage limitation: no fixed period; you set and justify it per purpose. | H2: Art. 7(1): the controller must be able to demonstrate consent. Art. 7(3): withdrawal as easy as giving.
A3: Nigeria | B3: NDPA 2023 + General Application and Implementation Directive 2025 | C3: 72 hours to the Commission | D3: Reported as immediately where the breach is likely to result in high risk (GAID Art. 33). UNVERIFIED - the Commission portal was unreachable during research; confirm article, date and wording with the NDPC before relying on it. | E3: Yes, with equivalent public-interest and legal-obligation exceptions | F3: No blanket localisation. Cross-border transfer requires an adequacy finding or an approved instrument. | G3: Purpose-limited; sector rules (financial, telecoms) impose their own periods. | H3: Consent must be freely given, specific, informed and demonstrable; separate consent for each purpose.
A4: Kenya | B4: Data Protection Act 2019 | C4: Without delay, within 72 hours of becoming aware (s.43(1)(a)) | D4: Without delay where there is a real risk of harm | E4: Yes - right to erasure and to object | F4: Section 50 lets the Cabinet Secretary prescribe processing through a server or data centre in Kenya on strategic-interest or revenue grounds. No general localisation mandate has been made under it, though sector-specific transfer restrictions exist (e.g. Civil Registration Regulations 2020). | G4: Retention only as long as necessary for the purpose. | H4: Consent must be express, unequivocal, free, specific and informed.
A5: South Africa | B5: POPIA (Act 4 of 2013) | C5: As soon as reasonably possible after discovery, to the Information Regulator | D5: As soon as reasonably possible after discovery, to the data subject | E5: Yes - deletion or destruction where the record is no longer authorised to be retained | F5: Section 72 restricts transfers absent adequate protection, consent or contract necessity. | G5: Retain only as long as necessary unless another law requires longer. | H5: Consent must be voluntary, specific and informed; the responsible party bears the burden of proof.
A6: United States - HIPAA | B6: 45 CFR Parts 160 and 164 | C6: HHS within 60 days if 500+ individuals affected; annually otherwise | D6: Individuals without unreasonable delay and no later than 60 days | E6: No general erasure right; amendment and accounting-of-disclosures rights instead | F6: No federal localisation requirement. | G6: Documentation retained 6 years (Sec. 164.316(b)(2)(i)); state medical-record laws often require longer. | H6: Authorization is the analogue of consent and is form-specified; treatment/payment/operations need none.
A7: United States - state privacy | B7: CCPA/CPRA and successor state statutes | C7: Not in CCPA itself; California Civ. Code Sec. 1798.82 requires notice in the most expedient time possible | D7: Same statute - most expedient time possible, without unreasonable delay | E7: Yes - right to delete, with enumerated exceptions | F7: No localisation requirement. | G7: Disclose retention periods, or the criteria used to set them, at collection. | H7: Opt-out model for sale/sharing, with opt-in for minors; consent is not the default basis.
A8: PCI DSS v4.0.1 | B8: Payment Card Industry Data Security Standard | C8: Card-brand and acquirer rules, not a statute - typically immediate | D8: Not applicable; downstream notification follows the applicable privacy law | E8: Not applicable; sensitive authentication data must not be retained after authorisation at all | F8: No localisation requirement in the standard. | G8: Req. 10.5.1: 12 months of audit history, with at least the last 3 months immediately available for analysis. | H8: Req. 10.2.2 fixes the fields every audit record must contain - model them as columns, not free text.
A10: This table is a design aid for schema decisions, not legal advice. Clocks, thresholds and exemptions change; confirm each against the current instrument and take advice for your jurisdictions. The design consequence is the same in every row: a breach record needs a per-regime deadline column and a recorded rationale for each notification made or withheld, because you cannot run every regime to the slowest clock.

Sheet Authenticators
A1: Authenticator | B1: Factor(s) | C1: Assurance ceiling | D1: Phishing-resistant | E1: Verifier-impersonation-resistant | F1: Schema fields it needs | G1: Notes and evidence
A2: Password (memorised secret) | B2: Something you know | C2: AAL1 alone; contributes to AAL2/AAL3 with a second factor | D2: No | E2: No | F2: Argon2id or scrypt hash, algorithm and parameters, last-changed timestamp, breach-check timestamp | G2: 15-character minimum where it is the only factor (8 when combined with another factor). No composition rules. No forced rotation except on evidence of compromise. Screen against known-breached lists (SHALL). Password managers and autofill SHALL be allowed; pasting SHOULD be permitted where autofill is unavailable. No hints, no knowledge-based questions.
A3: Passkey, synced | B3: Something you have + user verification | C3: AAL2 maximum | D3: Yes | E3: Yes | F3: credential_id (up to 1023 bytes, store as bytea), COSE public key, sign_count, transports, AAGUID, uv_initialized, backup_eligible (immutable), backup_state (mutable) | G3: Cannot reach AAL3: syncable authenticators require the private key to be exportable, and the guidance states they SHALL NOT be used at AAL3. Providers are widely reported to return sign_count = 0 on every assertion (undocumented by the vendors) - a naive "reject unless new > stored" check then rejects those users.
